[2023-12-09 16:15:36,244] INFO _log() L224  127.0.0.1 - - [09/Dec/2023 16:15:36] "[31m[1mPOST /dataset/upload HTTP/1.1[0m" 400 - - call_trace=C:\Users\biaoz\OneDrive\Documentos\mvp-oscar-dataset\env\lib\site-packages\werkzeug\_internal.py L224 
[2023-12-09 16:16:45,926] INFO _log() L224  127.0.0.1 - - [09/Dec/2023 16:16:45] "GET /dataset/download HTTP/1.1" 200 - - call_trace=C:\Users\biaoz\OneDrive\Documentos\mvp-oscar-dataset\env\lib\site-packages\werkzeug\_internal.py L224 
[2023-12-09 16:18:32,592] INFO _log() L224   * Running on http://127.0.0.1:5000 (Press CTRL+C to quit) - call_trace=C:\Users\biaoz\OneDrive\Documentos\mvp-oscar-dataset\env\lib\site-packages\werkzeug\_internal.py L224 
[2023-12-09 16:18:41,266] WARNING getExcel() L44   Erro ao tratar arquivo Excel, Erro ao tratar arquivo Excel - call_trace=C:\Users\biaoz\OneDrive\Documentos\mvp-oscar-dataset\app.py L44  
[2023-12-09 16:18:41,267] INFO _log() L224  127.0.0.1 - - [09/Dec/2023 16:18:41] "[31m[1mPOST /dataset/upload HTTP/1.1[0m" 400 - - call_trace=C:\Users\biaoz\OneDrive\Documentos\mvp-oscar-dataset\env\lib\site-packages\werkzeug\_internal.py L224 
[2023-12-09 16:21:11,469] WARNING getExcel() L44   Erro ao tratar arquivo Excel, Erro ao tratar arquivo Excel - call_trace=C:\Users\biaoz\OneDrive\Documentos\mvp-oscar-dataset\app.py L44  
[2023-12-09 16:21:11,470] INFO _log() L224  127.0.0.1 - - [09/Dec/2023 16:21:11] "[31m[1mPOST /dataset/upload HTTP/1.1[0m" 400 - - call_trace=C:\Users\biaoz\OneDrive\Documentos\mvp-oscar-dataset\env\lib\site-packages\werkzeug\_internal.py L224 
[2023-12-09 16:21:35,563] WARNING getExcel() L44   Erro ao tratar arquivo Excel, Erro ao tratar arquivo Excel - call_trace=C:\Users\biaoz\OneDrive\Documentos\mvp-oscar-dataset\app.py L44  
[2023-12-09 16:21:35,564] INFO _log() L224  127.0.0.1 - - [09/Dec/2023 16:21:35] "[31m[1mPOST /dataset/upload HTTP/1.1[0m" 400 - - call_trace=C:\Users\biaoz\OneDrive\Documentos\mvp-oscar-dataset\env\lib\site-packages\werkzeug\_internal.py L224 
[2023-12-09 16:22:27,748] WARNING getExcel() L44   Erro ao tratar arquivo Excel, Erro ao tratar arquivo Excel - call_trace=C:\Users\biaoz\OneDrive\Documentos\mvp-oscar-dataset\app.py L44  
[2023-12-09 16:22:27,749] INFO _log() L224  127.0.0.1 - - [09/Dec/2023 16:22:27] "[31m[1mPOST /dataset/upload HTTP/1.1[0m" 400 - - call_trace=C:\Users\biaoz\OneDrive\Documentos\mvp-oscar-dataset\env\lib\site-packages\werkzeug\_internal.py L224 
[2023-12-09 16:22:58,427] INFO _log() L224   * Running on http://127.0.0.1:5000 (Press CTRL+C to quit) - call_trace=C:\Users\biaoz\OneDrive\Documentos\mvp-oscar-dataset\env\lib\site-packages\werkzeug\_internal.py L224 
[2023-12-09 16:23:03,320] INFO _log() L224  127.0.0.1 - - [09/Dec/2023 16:23:03] "POST /dataset/upload HTTP/1.1" 200 - - call_trace=C:\Users\biaoz\OneDrive\Documentos\mvp-oscar-dataset\env\lib\site-packages\werkzeug\_internal.py L224 
[2023-12-09 16:26:07,507] INFO _log() L224   * Running on http://127.0.0.1:5000 (Press CTRL+C to quit) - call_trace=C:\Users\biaoz\OneDrive\Documentos\mvp-oscar-dataset\env\lib\site-packages\werkzeug\_internal.py L224 
[2023-12-09 16:26:16,655] ERROR log_exception() L1449 Exception on /dataset/upload [POST] - call_trace=C:\Users\biaoz\OneDrive\Documentos\mvp-oscar-dataset\env\lib\site-packages\flask\app.py L1449
Traceback (most recent call last):
  File "C:\Users\biaoz\OneDrive\Documentos\mvp-oscar-dataset\env\lib\site-packages\flask\app.py", line 2073, in wsgi_app
    response = self.full_dispatch_request()
  File "C:\Users\biaoz\OneDrive\Documentos\mvp-oscar-dataset\env\lib\site-packages\flask\app.py", line 1520, in full_dispatch_request
    return self.finalize_request(rv)
  File "C:\Users\biaoz\OneDrive\Documentos\mvp-oscar-dataset\env\lib\site-packages\flask\app.py", line 1539, in finalize_request
    response = self.make_response(rv)
  File "C:\Users\biaoz\OneDrive\Documentos\mvp-oscar-dataset\env\lib\site-packages\flask\app.py", line 1714, in make_response
    rv = jsonify(rv)
  File "C:\Users\biaoz\OneDrive\Documentos\mvp-oscar-dataset\env\lib\site-packages\flask\json\__init__.py", line 302, in jsonify
    f"{dumps(data, indent=indent, separators=separators)}\n",
  File "C:\Users\biaoz\OneDrive\Documentos\mvp-oscar-dataset\env\lib\site-packages\flask\json\__init__.py", line 132, in dumps
    return _json.dumps(obj, **kwargs)
  File "C:\Users\biaoz\AppData\Local\Programs\Python\Python310\lib\json\__init__.py", line 238, in dumps
    **kw).encode(obj)
  File "C:\Users\biaoz\AppData\Local\Programs\Python\Python310\lib\json\encoder.py", line 199, in encode
    chunks = self.iterencode(o, _one_shot=True)
  File "C:\Users\biaoz\AppData\Local\Programs\Python\Python310\lib\json\encoder.py", line 257, in iterencode
    return _iterencode(o, 0)
  File "C:\Users\biaoz\OneDrive\Documentos\mvp-oscar-dataset\env\lib\site-packages\flask\json\__init__.py", line 51, in default
    return super().default(o)
  File "C:\Users\biaoz\AppData\Local\Programs\Python\Python310\lib\json\encoder.py", line 179, in default
    raise TypeError(f'Object of type {o.__class__.__name__} '
TypeError: Object of type ndarray is not JSON serializable
[2023-12-09 16:26:16,665] INFO _log() L224  127.0.0.1 - - [09/Dec/2023 16:26:16] "[35m[1mPOST /dataset/upload HTTP/1.1[0m" 500 - - call_trace=C:\Users\biaoz\OneDrive\Documentos\mvp-oscar-dataset\env\lib\site-packages\werkzeug\_internal.py L224 
[2023-12-09 16:26:32,589] INFO _log() L224   * Running on http://127.0.0.1:5000 (Press CTRL+C to quit) - call_trace=C:\Users\biaoz\OneDrive\Documentos\mvp-oscar-dataset\env\lib\site-packages\werkzeug\_internal.py L224 
[2023-12-09 16:26:40,064] ERROR log_exception() L1449 Exception on /dataset/upload [POST] - call_trace=C:\Users\biaoz\OneDrive\Documentos\mvp-oscar-dataset\env\lib\site-packages\flask\app.py L1449
Traceback (most recent call last):
  File "C:\Users\biaoz\OneDrive\Documentos\mvp-oscar-dataset\env\lib\site-packages\flask\app.py", line 2073, in wsgi_app
    response = self.full_dispatch_request()
  File "C:\Users\biaoz\OneDrive\Documentos\mvp-oscar-dataset\env\lib\site-packages\flask\app.py", line 1520, in full_dispatch_request
    return self.finalize_request(rv)
  File "C:\Users\biaoz\OneDrive\Documentos\mvp-oscar-dataset\env\lib\site-packages\flask\app.py", line 1539, in finalize_request
    response = self.make_response(rv)
  File "C:\Users\biaoz\OneDrive\Documentos\mvp-oscar-dataset\env\lib\site-packages\flask\app.py", line 1714, in make_response
    rv = jsonify(rv)
  File "C:\Users\biaoz\OneDrive\Documentos\mvp-oscar-dataset\env\lib\site-packages\flask\json\__init__.py", line 302, in jsonify
    f"{dumps(data, indent=indent, separators=separators)}\n",
  File "C:\Users\biaoz\OneDrive\Documentos\mvp-oscar-dataset\env\lib\site-packages\flask\json\__init__.py", line 132, in dumps
    return _json.dumps(obj, **kwargs)
  File "C:\Users\biaoz\AppData\Local\Programs\Python\Python310\lib\json\__init__.py", line 238, in dumps
    **kw).encode(obj)
  File "C:\Users\biaoz\AppData\Local\Programs\Python\Python310\lib\json\encoder.py", line 199, in encode
    chunks = self.iterencode(o, _one_shot=True)
  File "C:\Users\biaoz\AppData\Local\Programs\Python\Python310\lib\json\encoder.py", line 257, in iterencode
    return _iterencode(o, 0)
  File "C:\Users\biaoz\OneDrive\Documentos\mvp-oscar-dataset\env\lib\site-packages\flask\json\__init__.py", line 51, in default
    return super().default(o)
  File "C:\Users\biaoz\AppData\Local\Programs\Python\Python310\lib\json\encoder.py", line 179, in default
    raise TypeError(f'Object of type {o.__class__.__name__} '
TypeError: Object of type ndarray is not JSON serializable
[2023-12-09 16:26:40,069] INFO _log() L224  127.0.0.1 - - [09/Dec/2023 16:26:40] "[35m[1mPOST /dataset/upload HTTP/1.1[0m" 500 - - call_trace=C:\Users\biaoz\OneDrive\Documentos\mvp-oscar-dataset\env\lib\site-packages\werkzeug\_internal.py L224 
[2023-12-09 16:27:11,503] INFO _log() L224   * Running on http://127.0.0.1:5000 (Press CTRL+C to quit) - call_trace=C:\Users\biaoz\OneDrive\Documentos\mvp-oscar-dataset\env\lib\site-packages\werkzeug\_internal.py L224 
